Workbook

Sheet Cover
C11: Project Evaluation
C13: Table of Contents | K13: Author And Course Info
C15: Cover | K15: Student Name: Abdalmalik Sabri
C16: Model | K16: Student Number: 0225555
K17: Email: aboodsabri2004@gmail.com
C22: This project evaluates the NPV,IRR,PI,PBP
C23: of a Fictional Project | K23: Color | L23: Meaning
K24: Blue | L24: Hard-coded inputs
K25: Black | L25: Calculations / Formulas

Sheet Model
B2: Assumptions & Drivers
B3: 1 | C3: 0 | D3: =C3+1 -> 1 | E3: =D3+1 -> 2 | F3: =E3+1 -> 3 | G3: =F3+1 -> 4 | H3: =G3+1 -> 5 | I3: salvage value | J3: =D10-(SUM(D17:H17)) -> 5760
B4: production | D4: =CHOOSE($B$3,Sheet2!D2,Sheet2!D12,Sheet2!D22) -> 5000 | E4: =CHOOSE($B$3,Sheet2!E2,Sheet2!E12,Sheet2!E22) -> 8000 | F4: =CHOOSE($B$3,Sheet2!F2,Sheet2!F12,Sheet2!F22) -> 12000 | G4: =CHOOSE($B$3,Sheet2!G2,Sheet2!G12,Sheet2!G22) -> 10000 | H4: =CHOOSE($B$3,Sheet2!H2,Sheet2!H12,Sheet2!H22) -> 6000 | I4: machine sale value | J4: 30000
B5: price | D5: =CHOOSE($B$3,Sheet2!D3,Sheet2!D13,Sheet2!D23) -> 20 | E5: =CHOOSE($B$3,Sheet2!E3,Sheet2!E13,Sheet2!E23) -> 20.4 | F5: =CHOOSE($B$3,Sheet2!F3,Sheet2!F13,Sheet2!F23) -> 20.808 | G5: =CHOOSE($B$3,Sheet2!G3,Sheet2!G13,Sheet2!G23) -> 21.22416 | H5: =CHOOSE($B$3,Sheet2!H3,Sheet2!H13,Sheet2!H23) -> 21.648643 | I5: value after tax | J5: =J4-((J4-J3)*H11) -> 21758.4
B6: production cost | D6: =CHOOSE($B$3,Sheet2!D4,Sheet2!D14,Sheet2!D24) -> 10 | E6: =CHOOSE($B$3,Sheet2!E4,Sheet2!E14,Sheet2!E24) -> 11 | F6: =CHOOSE($B$3,Sheet2!F4,Sheet2!F14,Sheet2!F24) -> 12.1 | G6: =CHOOSE($B$3,Sheet2!G4,Sheet2!G14,Sheet2!G24) -> 13.31 | H6: =CHOOSE($B$3,Sheet2!H4,Sheet2!H14,Sheet2!H24) -> 14.641
B7: inflation rate | D7: =CHOOSE($B$3,Sheet2!D5,Sheet2!D15,Sheet2!D25) -> 0.05 | E7: =CHOOSE($B$3,Sheet2!E5,Sheet2!E15,Sheet2!E25) -> 0.05 | F7: =CHOOSE($B$3,Sheet2!F5,Sheet2!F15,Sheet2!F25) -> 0.05 | G7: =CHOOSE($B$3,Sheet2!G5,Sheet2!G15,Sheet2!G25) -> 0.05 | H7: =CHOOSE($B$3,Sheet2!H5,Sheet2!H15,Sheet2!H25) -> 0.05
B8: working capital | C8: 10000 | D8: =(0.1*D15) -> 10000 | E8: =(0.1*E15) -> 16320 | F8: =(0.1*F15) -> 24969.6 | G8: =(0.1*G15) -> 21224.16 | H8: =(0.1*H15) -> 12989.186
B9: depreciation (%) | D9: 0.2 | E9: 0.32 | F9: 0.192 | G9: 0.1152 | H9: 0.1152
B10: depreciation | D10: 100000 | E10: 100000 | F10: 100000 | G10: 100000 | H10: 100000
B11: tax (%) | D11: =CHOOSE($B$3,Sheet2!D9,Sheet2!D19,Sheet2!D29) -> 0.34 | E11: =CHOOSE($B$3,Sheet2!E9,Sheet2!E19,Sheet2!E29) -> 0.34 | F11: =CHOOSE($B$3,Sheet2!F9,Sheet2!F19,Sheet2!F29) -> 0.34 | G11: =CHOOSE($B$3,Sheet2!G9,Sheet2!G19,Sheet2!G29) -> 0.34 | H11: =CHOOSE($B$3,Sheet2!H9,Sheet2!H19,Sheet2!H29) -> 0.34
B13: Income Statement
C14: 0 | D14: =C14+1 -> 1 | E14: =D14+1 -> 2 | F14: =E14+1 -> 3 | G14: =F14+1 -> 4 | H14: =G14+1 -> 5
B15: sales revenues | D15: =D4*D5 -> 100000 | E15: =E4*E5 -> 163200 | F15: =F4*F5 -> 249696 | G15: =G4*G5 -> 212241.6 | H15: =H4*H5 -> 129891.86
B16: operating costs | D16: =D6*D4 -> 50000 | E16: =E6*E4 -> 88000 | F16: =F6*F4 -> 145200 | G16: =G6*G4 -> 133100 | H16: =H6*H4 -> 87846
B17: depreciation | D17: =D9*D10 -> 20000 | E17: =E9*E10 -> 32000 | F17: =F9*F10 -> 19200 | G17: =G9*G10 -> 11520 | H17: =H9*H10 -> 11520
B18: income before taxes | D18: =D15-D16-D17 -> 30000 | E18: =E15-E16-E17 -> 43200 | F18: =F15-F16-F17 -> 85296 | G18: =G15-G16-G17 -> 67621.6 | H18: =H15-H16-H17 -> 30525.859
B19: ="tax at " & D11 -> tax at 0.34 | D19: =D18*D11 -> 10200 | E19: =E18*E11 -> 14688 | F19: =F18*F11 -> 29000.64 | G19: =G18*G11 -> 22991.344 | H19: =H18*H11 -> 10378.792
B20: net income | D20: =D18-D19 -> 19800 | E20: =E18-E19 -> 28512 | F20: =F18-F19 -> 56295.36 | G20: =G18-G19 -> 44630.256 | H20: =H18-H19 -> 20147.067
B22: Operating Cash Flow
C23: 0 | D23: =C23+1 -> 1 | E23: =D23+1 -> 2 | F23: =E23+1 -> 3 | G23: =F23+1 -> 4 | H23: =G23+1 -> 5
B24: net income | D24: =D20 -> 19800 | E24: =E20 -> 28512 | F24: =F20 -> 56295.36 | G24: =G20 -> 44630.256 | H24: =H20 -> 20147.067
B25: deprecation | D25: =D17 -> 20000 | E25: =E17 -> 32000 | F25: =F17 -> 19200 | G25: =G17 -> 11520 | H25: =H17 -> 11520
B26: OCF | D26: =D24+D25 -> 39800 | E26: =E24+E25 -> 60512 | F26: =F24+F25 -> 75495.36 | G26: =G24+G25 -> 56150.256 | H26: =H24+H25 -> 31667.067
B28: Net Working Capital
C29: 0 | D29: =C29+1 -> 1 | E29: =D29+1 -> 2 | F29: =E29+1 -> 3 | G29: =F29+1 -> 4 | H29: =G29+1 -> 5
B30: NWC | C30: =C8 -> 10000 | D30: =D8 -> 10000 | E30: =E8 -> 16320 | F30: =F8 -> 24969.6 | G30: =G8 -> 21224.16 | H30: =H8 -> 12989.186
B31: initial NWC | C31: =-C30 -> -10000
B32: change in NWC | D32: =C30-D30 -> 0 | E32: =D30-E30 -> -6320 | F32: =E30-F30 -> -8649.6 | G32: =F30-G30 -> 3745.44 | H32: =G30-H30 -> 8234.9741
B33: NWC recovery | H33: =H30 -> 12989.186
B34: total change in NWC | C34: =C31+C32+C33 -> -10000 | D34: =D31+D32+D33 -> 0 | E34: =E31+E32+E33 -> -6320 | F34: =F31+F32+F33 -> -8649.6 | G34: =G31+G32+G33 -> 3745.44 | H34: =H31+H32+H33 -> 21224.16
B36: Capital Spending
C37: 0 | D37: =C37+1 -> 1 | E37: =D37+1 -> 2 | F37: =E37+1 -> 3 | G37: =F37+1 -> 4 | H37: =G37+1 -> 5
B38: Initial Investment | C38: -100000 | H38: 21758.4
B39: Opportunity Cost | C39: -150000 | H39: 150000
B40: total change in NWC | C40: =C34 -> -10000 | D40: =D34 -> 0 | E40: =E34 -> -6320 | F40: =F34 -> -8649.6 | G40: =G34 -> 3745.44 | H40: =H34 -> 21224.16
B41: Total Capital Spending | C41: =SUM(C38:C40) -> -260000 | D41: =SUM(D38:D40) -> 0 | E41: =SUM(E38:E40) -> -6320 | F41: =SUM(F38:F40) -> -8649.6 | G41: =SUM(G38:G40) -> 3745.44 | H41: =SUM(H38:H40) -> 192982.56
B43: NPV
C44: 0 | D44: =C44+1 -> 1 | E44: =D44+1 -> 2 | F44: =E44+1 -> 3 | G44: =F44+1 -> 4 | H44: =G44+1 -> 5
B45: OCF | C45: =C26 -> 0 | D45: =D26 -> 39800 | E45: =E26 -> 60512 | F45: =F26 -> 75495.36 | G45: =G26 -> 56150.256 | H45: =H26 -> 31667.067
B46: Total Capital Spending | C46: =C41 -> -260000 | D46: =D41 -> 0 | E46: =E41 -> -6320 | F46: =F41 -> -8649.6 | G46: =G41 -> 3745.44 | H46: =H41 -> 192982.56
...

Sheet Sheet2
A1: base case
B2: production | D2: 5000 | E2: 8000 | F2: 12000 | G2: 10000 | H2: 6000
B3: price | D3: 20 | E3: 20.4 | F3: 20.808 | G3: 21.22416 | H3: 21.648643
B4: production cost | D4: 10 | E4: 11 | F4: 12.1 | G4: 13.31 | H4: 14.641
B5: inflation rate | D5: 0.05 | E5: 0.05 | F5: 0.05 | G5: 0.05 | H5: 0.05
B6: working capital | C6: 10000 | D6: 10000 | E6: 16320 | F6: 24969.6 | G6: 21224.16 | H6: 12989.186
B7: depreciation (%) | D7: 0.2 | E7: 0.32 | F7: 0.192 | G7: 0.1152 | H7: 0.1152
B8: depreciation | D8: 100000 | E8: 100000 | F8: 100000 | G8: 100000 | H8: 100000
B9: tax (%) | D9: 0.34 | E9: 0.34 | F9: 0.34 | G9: 0.34 | H9: 0.34
A11: best case
B12: production | D12: 5300 | E12: 8200 | F12: 12100 | G12: 10100 | H12: 6100 | J12: base case
B13: price | D13: 20 | E13: =D13*(1+0.03) -> 20.6 | F13: =E13*(1+0.03) -> 21.218 | G13: =F13*(1+0.03) -> 21.85454 | H13: =G13*(1+0.03) -> 22.510176 | J13: best case
B14: production cost | D14: 9.2 | E14: =D14*(1.1) -> 10.12 | F14: =E14*(1.1) -> 11.132 | G14: =F14*(1.1) -> 12.2452 | H14: =G14*(1.1) -> 13.46972 | J14: worst case
B15: inflation rate | D15: 0.04 | E15: 0.04 | F15: 0.04 | G15: 0.04 | H15: 0.04
B16: working capital | C16: 10000 | D16: 10000 | E16: 16320 | F16: 24969.6 | G16: 21224.16 | H16: 12989.186
B17: depreciation (%) | D17: 0.2 | E17: 0.32 | F17: 0.192 | G17: 0.1152 | H17: 0.1152
B18: depreciation | D18: 100000 | E18: 100000 | F18: 100000 | G18: 100000 | H18: 100000
B19: tax (%) | D19: 0.33 | E19: 0.33 | F19: 0.33 | G19: 0.33 | H19: 0.33
A21: worst case
B22: production | D22: 4500 | E22: 7000 | F22: 11500 | G22: 9000 | H22: 5500
B23: price | D23: 20 | E23: =D23*(1+0.01) -> 20.2 | F23: =E23*(1+0.01) -> 20.402 | G23: =F23*(1+0.01) -> 20.60602 | H23: =G23*(1+0.01) -> 20.81208
B24: production cost | D24: 11 | E24: =D24*(1.1) -> 12.1 | F24: =E24*(1.1) -> 13.31 | G24: =F24*(1.1) -> 14.641 | H24: =G24*(1.1) -> 16.1051
B25: inflation rate | D25: 0.06 | E25: 0.06 | F25: 0.06 | G25: 0.06 | H25: 0.06
B26: working capital | C26: 10000 | D26: 10000 | E26: 16320 | F26: 24969.6 | G26: 21224.16 | H26: 12989.186
B27: depreciation (%) | D27: 0.2 | E27: 0.32 | F27: 0.192 | G27: 0.1152 | H27: 0.1152
B28: depreciation | D28: 100000 | E28: 100000 | F28: 100000 | G28: 100000 | H28: 100000
B29: tax (%) | D29: 0.35 | E29: 0.35 | F29: 0.35 | G29: 0.35 | H29: 0.35
