Workbook

Sheet Cover
C11: Econometrics Project: Multiple Regression Analysis & Diagnostic Testing
C13: Table of Contents | K13: Project, Author And Course Info
C15: Raw Data | K15: • Student Name: Abdalmalik Sabri
C16: Clean Data | K16: • Student Number: 0225555
C17: Descriptive Statistics | K17: • Email: aboodsabri2004@gmail.com
C18: Correlation Matrix | K18: • Professor: Diana Abughunmi
C19: Regression Output | K19: • Course: Research Methods in Finance Section 2
C20: White's Test | K20: • Country Selected: Türkiye
C21: Durbin-Watson Test | K21: • Sample Period: 1995–2024 (30 annual observations)
C22: Charts & Graphs | K22: • Dependent Variable: GDP Growth Rate (% annual)
K23: • Independent Variables: Inflation, (GCF), Unemployment
K24: Data Source: World Bank WDI
C25: This project investigates the determinants of economic growth using multiple
C26: regression analysis and econometric diagnostic testing in Microsoft Excel.
C27: The study evaluates the relationships between GDP growth and selected
C28: macroeconomic indicators using annual World Bank data.

Sheet Raw Data
A1: Country Name | B1: Turkiye | C1: Turkiye | D1: Turkiye | E1: Turkiye
A2: Country Code | B2: TUR | C2: TUR | D2: TUR | E2: TUR
A3: Indicator Name | B3: GDP growth (annual %) | C3: Inflation, consumer prices (annual %) | D3: Gross capital formation (% of GDP) | E3: Unemployment, total (% of total labor force) (modeled ILO estimate)
A4: Indicator Code | B4: NY.GDP.MKTP.KD.ZG | C4: FP.CPI.TOTL.ZG | D4: NE.GDI.TOTL.ZS | E4: SL.UEM.TOTL.ZS
A5: 1995 | B5: 7.8782669 | C5: 89.113317 | D5: 27.402325 | E5: 7.644
A6: 1996 | B6: 7.1577985 | C6: 80.412151 | D6: 29.086116 | E6: 6.629
A7: 1997 | B7: 7.3578624 | C7: 85.669362 | D7: 27.027986 | E7: 6.841
A8: 1998 | B8: 1.9085706 | C8: 84.641343 | D8: 25.299763 | E8: 6.888
A9: 1999 | B9: -3.0527706 | C9: 64.867488 | D9: 21.504964 | E9: 7.687
A10: 2000 | B10: 6.985287 | C10: 54.915371 | D10: 24.011318 | E10: 6.495
A11: 2001 | B11: -5.4594084 | C11: 54.400189 | D11: 19.614362 | E11: 8.381
A12: 2002 | B12: 6.4355088 | C12: 44.964121 | D12: 21.525989 | E12: 10.358
A13: 2003 | B13: 5.7990932 | C13: 21.602438 | D13: 22.856781 | E13: 10.542
A14: 2004 | B14: 9.9254055 | C14: 8.5982617 | D14: 25.167773 | E14: 10.838
A15: 2005 | B15: 9.1115775 | C15: 8.1791604 | D15: 27.567471 | E15: 10.636
A16: 2006 | B16: 7.0676261 | C16: 9.5972421 | D16: 30.157715 | E16: 10.227
... A34: 2024 | B34: 3.3276231 | C34: 58.506451 | D34: 30.731156 | E34: 8.8

Sheet Clean Data
F1: University of Jordan
B2: Türkiye – ECONOMIC GROWTH REGRESSION DATASET (1995–2024)
B3: Source: World Bank World Development Indicators (WDI)
B5: Year | C5: GDP Growth Rate (%) | D5: Inflation Rate (%) | E5: GCF (% of GDP) | F5: Unemployment | G5: Residuals (e)
B6: 1995 | C6: 7.8782669 | D6: 89.113317 | E6: 27.402325 | F6: 7.644 | G6: ='Regression Output'!D26 -> 4.322478
B7: 1996 | C7: 7.1577985 | D7: 80.412151 | E7: 29.086116 | F7: 6.629 | G7: ='Regression Output'!D27 -> 1.1423141
B8: 1997 | C8: 7.3578624 | D8: 85.669362 | E8: 27.027986 | F8: 6.841 | G8: ='Regression Output'!D28 -> 2.8466298
B9: 1998 | C9: 1.9085706 | D9: 84.641343 | E9: 25.299763 | F9: 6.888 | G9: ='Regression Output'!D29 -> -1.8206802
B10: 1999 | C10: -3.0527706 | D10: 64.867488 | E10: 21.504964 | F10: 7.687 | G10: ='Regression Output'!D30 -> -5.3374319
B11: 2000 | C11: 6.985287 | D11: 54.915371 | E11: 24.011318 | F11: 6.495 | G11: ='Regression Output'!D31 -> 1.5861539
B12: 2001 | C12: -5.4594084 | D12: 54.400189 | E12: 19.614362 | F12: 8.381 | G12: ='Regression Output'!D32 -> -6.7239401
B13: 2002 | C13: 6.4355088 | D13: 44.964121 | E13: 21.525989 | F13: 10.358 | G13: ='Regression Output'!D33 -> 5.9789097
B14: 2003 | C14: 5.7990932 | D14: 21.602438 | E14: 22.856781 | F14: 10.542 | G14: ='Regression Output'!D34 -> 3.5204792
B15: 2004 | C15: 9.9254055 | D15: 8.5982617 | E15: 25.167773 | F15: 10.838 | G15: ='Regression Output'!D35 -> 6.1350087
B16: 2005 | C16: 9.1115775 | D16: 8.1791604 | E16: 27.567471 | F16: 10.636 | G16: ='Regression Output'!D36 -> 3.9667425
B17: 2006 | C17: 7.0676261 | D17: 9.5972421 | E17: 30.157715 | F17: 10.227 | G17: ='Regression Output'!D37 -> 0.35668046
... B35: 2024 | C35: 3.3276231 | D35: 58.506451 | E35: 30.731156 | F35: 8.8 | G35: ='Regression Output'!D55 -> -2.29598

Sheet Descriptive Statistics
F1: University of Jordan
B2: DESCRIPTIVE STATISTICS – Türkiye (1995–2024)
B4: Statistic | C4: GDP Growth (%) | D4: Inflation Rate (%) | E4: GCF (% of GDP) | F4: Unemployment
B5: Mean | C5: =AVERAGE('Clean Data'!C6:C35) -> 4.9610756 | D5: =AVERAGE('Clean Data'!D6:D35) -> 31.577967 | E5: =AVERAGE('Clean Data'!E6:E35) -> 28.652873 | F5: =AVERAGE('Clean Data'!F6:F35) -> 9.9837333
B6: Median | C6: =MEDIAN('Clean Data'!C6:C35) -> 5.6201592 | D6: =MEDIAN('Clean Data'!D6:D35) -> 13.72789 | E6: =MEDIAN('Clean Data'!E6:E35) -> 29.48544 | F6: =MEDIAN('Clean Data'!F6:F35) -> 10.2945
B7: Standard Deviation | C7: =STDEV('Clean Data'!C6:C35) -> 4.2198564 | D7: =STDEV('Clean Data'!D6:D35) -> 29.525781 | E7: =STDEV('Clean Data'!E6:E35) -> 4.348772 | F7: =STDEV('Clean Data'!F6:F35) -> 1.9679223
B8: Minimum | C8: =MIN('Clean Data'!C6:C35) -> -5.4594084 | D8: =MIN('Clean Data'!D6:D35) -> 6.2509766 | E8: =MIN('Clean Data'!E6:E35) -> 19.614362 | F8: =MIN('Clean Data'!F6:F35) -> 6.495
B9: Maximum | C9: =MAX('Clean Data'!C6:C35) -> 11.811094 | D9: =MAX('Clean Data'!D6:D35) -> 89.113317 | E9: =MAX('Clean Data'!E6:E35) -> 38.60214 | F9: =MAX('Clean Data'!F6:F35) -> 14.026
B11: Interpretation:
B12: • GDP Growth (%): Averaged 4.96%, but a wide range (-5.46% to 11.81%) and a high standard deviation (4.22%) highlight a highly volatile economic cycle.
B13: • Inflation Rate (%): Shows extreme price instability, averaging 31.58% with a massive peak of 89.11%, reflecting structural macroeconomic challenges.
B14: • Gross Capital Formation (%): Averaged a steady 28.65% acting as a consistent driver of economic output.
B15: • Unemployment Rate (%): Averaged 9.98% and never dropped below 6.495%, demonstrating chronic difficulties in absorbing the growing labor force.
B16: • Missing values: No missing observations were present in the World Bank WDI dataset for Türkiye over 1995–2024.

Sheet Correlation Matrix
F1: University of Jordan
B2: CORRELATION MATRIX – ALL VARIABLES
C4: GDP Growth (%) | D4: Inflation Rate (%) | E4: GCF (% of GDP) | F4: Unemployment
B5: GDP Growth (%) | C5: =CORREL('Clean Data'!$C$6:$C$35,'Clean Data'!C6:C35) -> 1 | D5: =CORREL('Clean Data'!$C$6:$C$35,'Clean Data'!D6:D35) -> -0.12088669 | E5: =CORREL('Clean Data'!$C$6:$C$35,'Clean Data'!E6:E35) -> 0.41227421 | F5: =CORREL('Clean Data'!$C$6:$C$35,'Clean Data'!F6:F35) -> -0.094028477
B6: Inflation Rate (%) | C6: =CORREL('Clean Data'!$D$6:$D$35,'Clean Data'!C6:C35) -> -0.12088669 | D6: =CORREL('Clean Data'!$D$6:$D$35,'Clean Data'!D6:D35) -> 1 | E6: =CORREL('Clean Data'!$D$6:$D$35,'Clean Data'!E6:E35) -> -0.18751541 | F6: =CORREL('Clean Data'!$D$6:$D$35,'Clean Data'!F6:F35) -> -0.73941924
B7: GCF (% of GDP) | C7: =CORREL('Clean Data'!$E$6:$E$35,'Clean Data'!C6:C35) -> 0.41227421 | D7: =CORREL('Clean Data'!$E$6:$E$35,'Clean Data'!D6:D35) -> -0.18751541 | E7: =CORREL('Clean Data'!$E$6:$E$35,'Clean Data'!E6:E35) -> 1 | F7: =CORREL('Clean Data'!$E$6:$E$35,'Clean Data'!F6:F35) -> 0.26155106
B8: Unemployment | C8: =CORREL('Clean Data'!$F$6:$F$35,'Clean Data'!C6:C35) -> -0.094028477 | D8: =CORREL('Clean Data'!$F$6:$F$35,'Clean Data'!D6:D35) -> -0.73941924 | E8: =CORREL('Clean Data'!$F$6:$F$35,'Clean Data'!E6:E35) -> 0.26155106 | F8: =CORREL('Clean Data'!$F$6:$F$35,'Clean Data'!F6:F35) -> 1
B10: Interpretation:
B11: • There is a moderate positive correlation (0.412) between GDP Growth and Gross Capital Formation, confirming that domestic investment directly supports economic expansion.
B12: • A strong negative correlation (-0.739) exists between the Inflation Rate and Unemployment, clearly reflecting a pronounced Phillips Curve effect within the Turkish economy
B13: • Both Inflation (-0.120) and Unemployment (-0.094) display weak negative correlations with GDP Growth, indicating these macroeconomic headwinds act as a drag on national output.
B14: • The most significant multicollinearity risk lies between Inflation and Unemployment; however, at -0.739, it remains below the standard 0.80 rejection threshold.
B15: • The correlation signs align perfectly with established macroeconomic theory, providing a mathematically sound and defensible foundation for the multiple regression model.

Sheet Regression Output
F1: University of Jordan
B2: REGRESSION OUTPUT – Türkiye GDP GROWTH MODEL
B4: Regression Statistics
B5: Multiple R | C5: 0.54409736
B6: R Square | C6: 0.29604193 | D6: • The regression explains 29.6% of the variation in GDP growth , indicating moderate explanatory
B7: Adjusted R Square | C7: 0.214816 | D7: power for macroeconomic time-series data.
B8: Standard Error | C8: 3.7392405
B9: Observations | C9: 30
B11: ANOVA
B12: Source | C12: df | D12: SS | E12: MS | F12: F | G12: Significance F
B13: Regression | C13: 3 | D13: 152.87856 | E13: 50.95952 | F13: 3.6446727 | G13: 0.025620083 | H13: • The overall regression model is statistically significant .Since
B14: Residual | C14: 26 | D14: 363.5299 | E14: 13.981919 | H14: the p-value is below 0.05, the null hypothesis that all slope
B15: Total | C15: 29 | D15: 516.40846 | H15: coefficients are jointly equal to zero is rejected.
B17: COEFFICIENTS TABLE
B18: Variable | C18: Coefficients | D18: Standard Error | E18: t Stat | F18: P-value | G18: Lower 95% | H18: Upper 95% | I18: Lower 95.0% | J18: Upper 95.0%
B19: Intercept | C19: 5.1722388 | D19: 7.182397 | E19: 0.72012711 | F19: 0.47787123 | G19: -9.5913897 | H19: 19.935867 | I19: -9.5913897 | J19: 19.935867
B20: Inflation Rate (X₁) | C20: -0.060915341 | D20: 0.034932324 | E20: -1.7438101 | F20: 0.093006648 | G20: -0.13271976 | H20: 0.01088908 | I20: -0.13271976 | J20: 0.01088908
B21: GCF (% of GDP) (X₂) | C21: 0.45765677 | D21: 0.16543328 | E21: 2.7664129 | F21: 0.010294522 | G21: 0.11760379 | H21: 0.79770976 | I21: 0.11760379 | J21: 0.79770976
B22: Unemployment (X₃) | C22: -1.1419337 | D22: 0.53337847 | E22: -2.1409446 | F22: 0.041824379 | G22: -2.2383089 | H22: -0.045558609 | I22: -2.2383089 | J22: -0.045558609
B24: RESIDUAL OUTPUT | F24: • Inflation is statistically significant only at the 10% significance level
B25: Observation | C25: Predicted GDP Growth Rate (%) | D25: Residuals | F25: suggesting weak statistical evidence of its effect on GDP growth.
B26: 1 | C26: 3.5557889 | D26: 4.322478 | F26: • Gross Capital Formation is statistically significant at the 5% level
B27: 2 | C27: 6.0154844 | D27: 1.1423141 | F27: making it the strongest predictor in the model.
B28: 3 | C28: 4.5112326 | D28: 2.8466298 | F28: • Unemployment Rate is statistically significant at the 5% level , showing that labor-market
B29: 4 | C29: 3.7292508 | D29: -1.8206802 | F29: conditions significantly affect economic growth in Türkiye.
B30: 5 | C30: 2.2846613 | D30: -5.3374319
B31: 6 | C31: 5.399133 | D31: 1.5861539 | F31: • The coefficient of Inflation Rate is negative, indicating that higher inflation is
B32: 7 | C32: 1.2645317 | D32: -6.7239401 | F32: associated with lower GDP growth. This is consistent with economic theory since inflation may reduce
B33: 8 | C33: 0.45659914 | D33: 5.9789097 | F33: purchasing power and increase economic uncertainty.
B34: 9 | C34: 2.2786141 | D34: 3.5204792 | F34: • The coefficient of GCF is positive, meaning that higher investment levels contribute positively to economic
B35: 10 | C35: 3.7903968 | D35: 6.1350087 | F35: growth by increasing productive capacity and capital accumulation.
B36: 11 | C36: 5.1448349 | D36: 3.9667425 | F36: • The coefficient of Unemployment Rate is negative, indicating that higher unemployment reduces GDP activity.
B37: 12 | C37: 6.7109456 | D37: 0.35668046 | F37: growth due to underutilization of labor resources and weaker economic activity.
B38: 13 | C38: 6.4175207 | D38: -1.3093356
B39: 14 | C39: 5.6191248 | D39: -4.6990065 | F39: • Overall, the regression results are generally consistent with economic theory, as investment positively affects
B40: 15 | C40: -0.38118394 | D40: -4.5015101 | F40: growth while inflation and unemployment negatively affect growth.
B41: 16 | C41: 4.1066661 | D41: 4.4355324
B42: 17 | C42: 8.2255388 | D42: 2.7544238 | F42: How could the regression model be improved?
B43: 18 | C43: 7.5783622 | D43: -2.7707353 | F43: The regression model could be improved by including additional macroeconomic variables such as exchange
B44: 19 | C44: 7.9785709 | D44: 0.509686 | F44: rates, government expenditure, interest rates, or trade indicators. Using a larger sample size and applying
...

Sheet White's Test
B1: University of Jordan
B2: WHITE'S TEST FOR HETEROSKEDASTICITY
B3: H₀: Homoskedasticity (constant variance of error terms)
B4: H₁: Heteroskedasticity (non-constant variance)
B5: Year | C5: e (Residual) | D5: e² (Residual)² | E5: X₁ | F5: X₂ | G5: X₃ | H5: X₁² | I5: X₂² | J5: X₃² | K5: X₁·X₂ | L5: X₁·X₃ | M5: X₂·X₃
B6: ='Clean Data'!B6 -> 1995 | C6: ='Clean Data'!G6 -> 4.322478 | D6: =C6^2 -> 18.683816 | E6: ='Clean Data'!D6 -> 89.113317 | F6: ='Clean Data'!E6 -> 27.402325 | G6: ='Clean Data'!F6 -> 7.644 | H6: =E6^2 -> 7941.1833 | I6: =F6^2 -> 750.88743 | J6: =G6^2 -> 58.430736 | K6: =E6*F6 -> 2441.9121 | L6: =E6*G6 -> 681.1822 | M6: =F6*G6 -> 209.46337
B7: ='Clean Data'!B7 -> 1996 | C7: ='Clean Data'!G7 -> 1.1423141 | D7: =C7^2 -> 1.3048816 | E7: ='Clean Data'!D7 -> 80.412151 | F7: ='Clean Data'!E7 -> 29.086116 | G7: ='Clean Data'!F7 -> 6.629 | H7: =E7^2 -> 6466.1141 | I7: =F7^2 -> 846.00214 | J7: =G7^2 -> 43.943641 | K7: =E7*F7 -> 2338.8771 | L7: =E7*G7 -> 533.05215 | M7: =F7*G7 -> 192.81186
B8: ='Clean Data'!B8 -> 1997 | C8: ='Clean Data'!G8 -> 2.8466298 | D8: =C8^2 -> 8.1033011 | E8: ='Clean Data'!D8 -> 85.669362 | F8: ='Clean Data'!E8 -> 27.027986 | G8: ='Clean Data'!F8 -> 6.841 | H8: =E8^2 -> 7339.2395 | I8: =F8^2 -> 730.51203 | J8: =G8^2 -> 46.799281 | K8: =E8*F8 -> 2315.4703 | L8: =E8*G8 -> 586.0641 | M8: =F8*G8 -> 184.89845
B9: ='Clean Data'!B9 -> 1998 | C9: ='Clean Data'!G9 -> -1.8206802 | D9: =C9^2 -> 3.3148763 | E9: ='Clean Data'!D9 -> 84.641343 | F9: ='Clean Data'!E9 -> 25.299763 | G9: ='Clean Data'!F9 -> 6.888 | H9: =E9^2 -> 7164.157 | I9: =F9^2 -> 640.07802 | J9: =G9^2 -> 47.444544 | K9: =E9*F9 -> 2141.4059 | L9: =E9*G9 -> 583.00957 | M9: =F9*G9 -> 174.26477
B10: ='Clean Data'!B10 -> 1999 | C10: ='Clean Data'!G10 -> -5.3374319 | D10: =C10^2 -> 28.488179 | E10: ='Clean Data'!D10 -> 64.867488 | F10: ='Clean Data'!E10 -> 21.504964 | G10: ='Clean Data'!F10 -> 7.687 | H10: =E10^2 -> 4207.791 | I10: =F10^2 -> 462.46347 | J10: =G10^2 -> 59.089969 | K10: =E10*F10 -> 1394.973 | L10: =E10*G10 -> 498.63638 | M10: =F10*G10 -> 165.30866
B11: ='Clean Data'!B11 -> 2000 | C11: ='Clean Data'!G11 -> 1.5861539 | D11: =C11^2 -> 2.5158843 | E11: ='Clean Data'!D11 -> 54.915371 | F11: ='Clean Data'!E11 -> 24.011318 | G11: ='Clean Data'!F11 -> 6.495 | H11: =E11^2 -> 3015.6979 | I11: =F11^2 -> 576.5434 | J11: =G11^2 -> 42.185025 | K11: =E11*F11 -> 1318.5904 | L11: =E11*G11 -> 356.67533 | M11: =F11*G11 -> 155.95351
B12: ='Clean Data'!B12 -> 2001 | C12: ='Clean Data'!G12 -> -6.7239401 | D12: =C12^2 -> 45.211371 | E12: ='Clean Data'!D12 -> 54.400189 | F12: ='Clean Data'!E12 -> 19.614362 | G12: ='Clean Data'!F12 -> 8.381 | H12: =E12^2 -> 2959.3805 | I12: =F12^2 -> 384.7232 | J12: =G12^2 -> 70.241161 | K12: =E12*F12 -> 1067.025 | L12: =E12*G12 -> 455.92798 | M12: =F12*G12 -> 164.38797
B13: ='Clean Data'!B13 -> 2002 | C13: ='Clean Data'!G13 -> 5.9789097 | D13: =C13^2 -> 35.747361 | E13: ='Clean Data'!D13 -> 44.964121 | F13: ='Clean Data'!E13 -> 21.525989 | G13: ='Clean Data'!F13 -> 10.358 | H13: =E13^2 -> 2021.7722 | I13: =F13^2 -> 463.36822 | J13: =G13^2 -> 107.28816 | K13: =E13*F13 -> 967.89719 | L13: =E13*G13 -> 465.73836 | M13: =F13*G13 -> 222.9662
B14: ='Clean Data'!B14 -> 2003 | C14: ='Clean Data'!G14 -> 3.5204792 | D14: =C14^2 -> 12.393773 | E14: ='Clean Data'!D14 -> 21.602438 | F14: ='Clean Data'!E14 -> 22.856781 | G14: ='Clean Data'!F14 -> 10.542 | H14: =E14^2 -> 466.66535 | I14: =F14^2 -> 522.43244 | J14: =G14^2 -> 111.13376 | K14: =E14*F14 -> 493.76221 | L14: =E14*G14 -> 227.73291 | M14: =F14*G14 -> 240.95619
B15: ='Clean Data'!B15 -> 2004 | C15: ='Clean Data'!G15 -> 6.1350087 | D15: =C15^2 -> 37.638332 | E15: ='Clean Data'!D15 -> 8.5982617 | F15: ='Clean Data'!E15 -> 25.167773 | G15: ='Clean Data'!F15 -> 10.838 | H15: =E15^2 -> 73.930104 | I15: =F15^2 -> 633.41682 | J15: =G15^2 -> 117.46224 | K15: =E15*F15 -> 216.3991 | L15: =E15*G15 -> 93.18796 | M15: =F15*G15 -> 272.76833
B16: ='Clean Data'!B16 -> 2005 | C16: ='Clean Data'!G16 -> 3.9667425 | D16: =C16^2 -> 15.735046 | E16: ='Clean Data'!D16 -> 8.1791604 | F16: ='Clean Data'!E16 -> 27.567471 | G16: ='Clean Data'!F16 -> 10.636 | H16: =E16^2 -> 66.898664 | I16: =F16^2 -> 759.96545 | J16: =G16^2 -> 113.1245 | K16: =E16*F16 -> 225.47877 | L16: =E16*G16 -> 86.99355 | M16: =F16*G16 -> 293.20762
B17: ='Clean Data'!B17 -> 2006 | C17: ='Clean Data'!G17 -> 0.35668046 | D17: =C17^2 -> 0.12722095 | E17: ='Clean Data'!D17 -> 9.5972421 | F17: ='Clean Data'!E17 -> 30.157715 | G17: ='Clean Data'!F17 -> 10.227 | H17: =E17^2 -> 92.107056 | I17: =F17^2 -> 909.48777 | J17: =G17^2 -> 104.59153 | K17: =E17*F17 -> 289.43089 | L17: =E17*G17 -> 98.150995 | M17: =F17*G17 -> 308.42295
... B35: ='Clean Data'!B35 -> 2024 | C35: ='Clean Data'!G35 -> -2.29598 | D35: =C35^2 -> 5.2715243 | E35: ='Clean Data'!D35 -> 58.506451 | F35: ='Clean Data'!E35 -> 30.731156 | G35: ='Clean Data'!F35 -> 8.8 | H35: =E35^2 -> 3423.0048 | I35: =F35^2 -> 944.40395 | J35: =G35^2 -> 77.44 | K35: =E35*F35 -> 1797.9709 | L35: =E35*G35 -> 514.85677 | M35: =F35*G35 -> 270.43417
B37: AUXILIARY REGRESSION RESULTS (Dependent Variable: e²)
B38: SUMMARY OUTPUT
B39: Regression Statistics | E39: Statistic | F39: Value
B40: Multiple R | C40: 0.79086605 | E40: Number of Obs(n) | F40: =C44 -> 30
B41: R Square | C41: 0.62546911 | E41: Auxiliary Regression R² | F41: =C41 -> 0.62546911
B42: Adjusted R Square | C42: 0.45693021 | E42: Test Statistic (n × R²) | F42: =F40*F41 -> 18.764073
B43: Standard Error | C43: 9.4557578 | E43: Degrees of Freedom | F43: 9
B44: Observations | C44: 30 | E44: χ² Critical Value (α = 5%) | F44: =_xlfn.CHISQ.INV.RT(0.05,F43) -> 16.918978
B46: CONCLUSION: Test Statistic (18.764) > χ²_critical (16.919) --- REJECT H₀ --- evidence of heteroskedasticity at 5% significance level.
B47: • the presence of heteroskedasticity may cause OLS standard errors to become biased and unreliable, affecting hypothesis testing and confidence intervals.
B48: • although the coefficient estimates remain unbiased, the statistical significance of variables should be interpreted with caution.

Sheet Durbin-Watson Test
B1: University of Jordan
B2: DURBIN-WATSON TEST FOR AUTOCORRELATION
B3: Formula: d = Σ(eₜ - eₜ₋₁)² / Σeₜ²
B4: Year | C4: Residual (eₜ) | D4: (eₜ - eₜ₋₁) | E4: (eₜ - eₜ₋₁)² | F4: eₜ² | H4: DURBIN-WATSON CALCULATION AND INTERPRETATION
B5: ='White''s Test'!B6 -> 1995 | C5: ='White''s Test'!C6 -> 4.322478 | D5: — | E5: — | F5: =C5^2 -> 18.683816
B6: ='White''s Test'!B7 -> 1996 | C6: ='White''s Test'!C7 -> 1.1423141 | D6: =C6-C5 -> -3.1801638 | E6: =D6^2 -> 10.113442 | F6: =C6^2 -> 1.3048816 | H6: Statistic | I6: Value | K6: CRITICAL VALUES (n=30, k=3)
B7: ='White''s Test'!B8 -> 1997 | C7: ='White''s Test'!C8 -> 2.8466298 | D7: =C7-C6 -> 1.7043157 | E7: =D7^2 -> 2.9046919 | F7: =C7^2 -> 8.1033011 | H7: Σ(eₜ - eₜ₋₁)² | I7: =SUM(E6:E34) -> 678.99769 | K7: Bound | L7: Value
B8: ='White''s Test'!B9 -> 1998 | C8: ='White''s Test'!C9 -> -1.8206802 | D8: =C8-C7 -> -4.66731 | E8: =D8^2 -> 21.783782 | F8: =C8^2 -> 3.3148763 | H8: Σeₜ² | I8: =SUM(F5:F34) -> 363.5299 | K8: dL (Lower b) | L8: 1.214
B9: ='White''s Test'!B10 -> 1999 | C9: ='White''s Test'!C10 -> -5.3374319 | D9: =C9-C8 -> -3.5167517 | E9: =D9^2 -> 12.367542 | F9: =C9^2 -> 28.488179 | H9: D-W Statistic | I9: =I7/I8 -> 1.8677905 | K9: dU (Upper b) | L9: 1.650
B10: ='White''s Test'!B11 -> 2000 | C10: ='White''s Test'!C11 -> 1.5861539 | D10: =C10-C9 -> 6.9235858 | E10: =D10^2 -> 47.93604 | F10: =C10^2 -> 2.5158843 | K10: 4 - dU | L10: 2.350
B11: ='White''s Test'!B12 -> 2001 | C11: ='White''s Test'!C12 -> -6.7239401 | D11: =C11-C10 -> -8.3100941 | E11: =D11^2 -> 69.057664 | F11: =C11^2 -> 45.211371 | K11: 4 - dL | L11: 2.786
B12: ='White''s Test'!B13 -> 2002 | C12: ='White''s Test'!C13 -> 5.9789097 | D12: =C12-C11 -> 12.70285 | E12: =D12^2 -> 161.36239 | F12: =C12^2 -> 35.747361 | H12: • d < dL ===Positive autocorrelation
B13: ='White''s Test'!B14 -> 2003 | C13: ='White''s Test'!C14 -> 3.5204792 | D13: =C13-C12 -> -2.4584305 | E13: =D13^2 -> 6.0438807 | F13: =C13^2 -> 12.393773 | H13: • d > 4- dL === Negative autocorrelation
B14: ='White''s Test'!B15 -> 2004 | C14: ='White''s Test'!C15 -> 6.1350087 | D14: =C14-C13 -> 2.6145296 | E14: =D14^2 -> 6.8357648 | F14: =C14^2 -> 37.638332 | H14: • dU < d < 4-dU (1.650–2.350) → No autocorrelation
B15: ='White''s Test'!B16 -> 2005 | C15: ='White''s Test'!C16 -> 3.9667425 | D15: =C15-C14 -> -2.1682662 | E15: =D15^2 -> 4.7013782 | F15: =C15^2 -> 15.735046
B16: ='White''s Test'!B17 -> 2006 | C16: ='White''s Test'!C17 -> 0.35668046 | D16: =C16-C15 -> -3.6100621 | E16: =D16^2 -> 13.032548 | F16: =C16^2 -> 0.12722095 | H16: • The Durbin–Watson statistic is close to 2, indicating no significant autocorrelation in the residuals.
B17: ='White''s Test'!B18 -> 2007 | C17: ='White''s Test'!C18 -> -1.3093356 | D17: =C17-C16 -> -1.666016 | E17: =D17^2 -> 2.7756094 | F17: =C17^2 -> 1.7143596 | H17: Therefore, the null hypothesis of no autocorrelation is not rejected.
B18: ='White''s Test'!B19 -> 2008 | C18: ='White''s Test'!C19 -> -4.6990065 | D18: =C18-C17 -> -3.389671 | E18: =D18^2 -> 11.489869 | F18: =C18^2 -> 22.080662 | H18: • This suggests that the residuals are independent over time and the OLS estimates remain reliable
B19: ='White''s Test'!B20 -> 2009 | C19: ='White''s Test'!C20 -> -4.5015101 | D19: =C19-C18 -> 0.19749647 | E19: =D19^2 -> 0.039004854 | F19: =C19^2 -> 20.263593 | H19: however, note that heteroskedasticity was found, so standard errors remain unreliable,
B20: ='White''s Test'!B21 -> 2010 | C20: ='White''s Test'!C21 -> 4.4355324 | D20: =C20-C19 -> 8.9370425 | E20: =D20^2 -> 79.870728 | F20: =C20^2 -> 19.673948
B21: ='White''s Test'!B22 -> 2011 | C21: ='White''s Test'!C22 -> 2.7544238 | D21: =C21-C20 -> -1.6811086 | E21: =D21^2 -> 2.8261263 | F21: =C21^2 -> 7.5868502 | H21: What does the Durbin-Watson statistic measure?
B22: ='White''s Test'!B23 -> 2012 | C22: ='White''s Test'!C23 -> -2.7707353 | D22: =C22-C21 -> -5.525159 | E22: =D22^2 -> 30.527382 | F22: =C22^2 -> 7.6769739 | H22: The Durbin-Watson statistic measures autocorrelation in the residuals of a regression model
B23: ='White''s Test'!B24 -> 2013 | C23: ='White''s Test'!C24 -> 0.509686 | D23: =C23-C22 -> 3.2804213 | E23: =D23^2 -> 10.761164 | F23: =C23^2 -> 0.25977982 | H23: It tests whether residuals are correlated across time periods.
B24: ='White''s Test'!B25 -> 2014 | C24: ='White''s Test'!C25 -> -2.5522945 | D24: =C24-C23 -> -3.0619805 | E24: =D24^2 -> 9.3757246 | F24: =C24^2 -> 6.5142072
B25: ='White''s Test'!B26 -> 2015 | C25: ='White''s Test'!C26 -> -0.89139638 | D25: =C25-C24 -> 1.6608981 | E25: =D25^2 -> 2.7585825 | F25: =C25^2 -> 0.79458752 | H25: Why is autocorrelation problematic in time-series regression?
B26: ='White''s Test'!B27 -> 2016 | C26: ='White''s Test'!C27 -> -2.580379 | D26: =C26-C25 -> -1.6889826 | E26: =D26^2 -> 2.8526622 | F26: =C26^2 -> 6.6583557 | H26: Autocorrelation violates one of the classical linear regression assumptions and may lead to inefficient
B27: ='White''s Test'!B28 -> 2017 | C27: ='White''s Test'!C28 -> 0.79253956 | D27: =C27-C26 -> 3.3729185 | E27: =D27^2 -> 11.376579 | F27: =C27^2 -> 0.62811895 | H27: OLS estimates and unreliable standard errors. This reduces the reliability of statistical inference.
B28: ='White''s Test'!B29 -> 2018 | C28: ='White''s Test'!C29 -> -2.5414918 | D28: =C28-C27 -> -3.3340314 | E28: =D28^2 -> 11.115765 | F28: =C28^2 -> 6.4591808
B29: ='White''s Test'!B30 -> 2019 | C29: ='White''s Test'!C30 -> 0.14440686 | D29: =C29-C28 -> 2.6858987 | E29: =D29^2 -> 7.2140518 | F29: =C29^2 -> 0.020853341
B30: ='White''s Test'!B31 -> 2020 | C30: ='White''s Test'!C31 -> -3.2378897 | D30: =C30-C29 -> -3.3822965 | E30: =D30^2 -> 11.43993 | F30: =C30^2 -> 10.48393
B31: ='White''s Test'!B32 -> 2021 | C31: ='White''s Test'!C32 -> 5.7679123 | D31: =C31-C30 -> 9.005802 | E31: =D31^2 -> 81.10447 | F31: =C31^2 -> 33.268813
B32: ='White''s Test'!B33 -> 2022 | C32: ='White''s Test'!C33 -> -1.0424904 | D32: =C32-C31 -> -6.8104027 | E32: =D32^2 -> 46.381585 | F32: =C32^2 -> 1.0867861
B33: ='White''s Test'!B34 -> 2023 | C33: ='White''s Test'!C34 -> -1.9553359 | D33: =C33-C32 -> -0.91284553 | E33: =D33^2 -> 0.83328696 | F33: =C33^2 -> 3.8233384
B34: ='White''s Test'!B35 -> 2024 | C34: ='White''s Test'!C35 -> -2.29598 | D34: =C34-C33 -> -0.34064416 | E34: =D34^2 -> 0.11603844 | F34: =C34^2 -> 5.2715243

Sheet Charts & Graphs
B1: University of Jordan
B2: CHARTS & GRAPHS – Türkiye REGRESSION ANALYSIS (1995–2024)
B4: GDP Growth Rate Vs Predicted Over Time | I4: Variables Over Time
B20: Residuals Over Time | I20: Impact of independent variables on GDP
